Workbook
Name IQ_CH: 110000
Name IQ_CQ: 5000
Name IQ_CY: 10000
Name IQ_DAILY: 500000
Name IQ_FH: 100000
Name IQ_FQ: 500
Name IQ_FY: 1000
Name IQ_LTM: 2000
Name IQ_MONTH: 15000
Name IQ_NTM: 6000
Name IQ_WEEK: 50000
Name IQ_YTD: 3000

Sheet README
A1: This model is an interactive model. Text in blue are hardcoded values and their origin is stated with a website link. All black text are formulas. Do not change the formulas. All worksheets are interconnected.
A2: Note: Saves of the model goes through a iterative process of updated tables so wait for the end of the save to complete before looking at IRR
A3: Glossary of Worksheets
A4: # | B4: Worksheet Name | C4: Type | D4: Description
A5: 1 | B5: graphs | C5: Summary | D5: provides various graphs based on the calculated data
A6: =SUM(A5+1) -> 2 | B6: Summary | C6: Summary | D6: Provides the summary of the calculations to include the IRR.
A7: =SUM(A6+1) -> 3 | B7: Data Sources | C7: Financial | D7: All inputs to the model are located on this worksheet. This is where you change items.
A8: =SUM(A7+1) -> 4 | B8: Inputs | C8: Financial | D8: Reads the Data sources values and calculates the yearly and monthly values
A9: =SUM(A8+1) -> 5 | B9: Project Equity | C9: Financial | D9: Assumes the CREC ownership and other partners equity then shows the equity flows out of the project
A10: =SUM(A9+1) -> 6 | B10: CapEx | C10: Financial | D10: Provides the equipment and engineering costs plus management reserve for the project. It also shows country origins of the equipment
A11: =SUM(A10+1) -> 7 | B11: Financials Yearly | C11: Financial | D11: Takes the monthly calculations in Financial worksheet and rolls it up to yearly values.
A12: =SUM(A11+1) -> 8 | B12: Quarterly | C12: Financial | D12: Takes the monthly calculations in Financial worksheet and rolls it up to quarterly values.
A13: =SUM(A12+1) -> 9 | B13: Financials | C13: Financial | D13: Calculates the monthly revenue and expenses for the project over 25 years
A14: =SUM(A13+1) -> 10 | B14: Capital Contributions | C14: Financial | D14: Shows the loans and interest rates and then does the draw downs and repayments back calculations
A15: =SUM(A14+1) -> 11 | B15: Insurance | C15: Financial | D15: Covers insuarnce costs for MIGA and technical Risk insurance
A16: =SUM(A15+1) -> 12 | B16: Cash Draw Down Schedule | C16: Financial | D16: Shows the drawdown schedule for the project on engineering and also the equipment ordering
A17: =SUM(A16+1) -> 13 | B17: NPV IRR | C17: Financial | D17: Net Present Value worksheet
... A29: =SUM(A28+1) -> 25 | B29: Job Descriptions | C29: Financial | D29: Description of each job type

Sheet graphs
B1: ='Financials Yearly'!C2 -> 2026 | C1: ='Financials Yearly'!D2 -> 2027 | D1: ='Financials Yearly'!E2 -> 2028 | E1: ='Financials Yearly'!F2 -> 2029 | F1: ='Financials Yearly'!G2 -> 2030 | G1: ='Financials Yearly'!H2 -> 2031 | H1: ='Financials Yearly'!I2 -> 2032 | I1: ='Financials Yearly'!J2 -> 2033 | ... X1: ='Financials Yearly'!Y2 -> 2048
A2: ='Financials Yearly'!B30 -> Total Revenue | B2: ='Financials Yearly'!C30 -> 0 | C2: ='Financials Yearly'!D30 -> 42079158 | D2: ='Financials Yearly'!E30 -> 73261683 | E2: ='Financials Yearly'!F30 -> 79804722 | F2: ='Financials Yearly'!G30 -> 81225242 | G2: ='Financials Yearly'!H30 -> 82228620 | H2: ='Financials Yearly'!I30 -> 83477384 | ... X2: ='Financials Yearly'!Y30 -> 1.072573e+08
A3: ='Financials Yearly'!B49 -> Total Expenses | B3: ='Financials Yearly'!C49 -> 4213882 | C3: ='Financials Yearly'!D49 -> 14503585 | D3: ='Financials Yearly'!E49 -> 16601801 | E3: ='Financials Yearly'!F49 -> 14831084 | F3: ='Financials Yearly'!G49 -> 14043197 | G3: ='Financials Yearly'!H49 -> 13700323 | H3: ='Financials Yearly'!I49 -> 13326671 | ... X3: ='Financials Yearly'!Y49 -> 11376319
A4: ='Financials Yearly'!B63 -> Interest Expense | B4: ='Financials Yearly'!C63 -> 9254241.3 | C4: ='Financials Yearly'!D63 -> 14539844 | D4: ='Financials Yearly'!E63 -> 12846521 | E4: ='Financials Yearly'!F63 -> 11888300 | F4: ='Financials Yearly'!G63 -> 11002521 | G4: ='Financials Yearly'!H63 -> 10052709 | H4: ='Financials Yearly'!I63 -> 9034234.5 | ... X4: ='Financials Yearly'!Y63 -> 0
A5: ='Financials Yearly'!B94 -> Debt Amortization Payments | B5: ='Financials Yearly'!C94 -> 0 | C5: ='Financials Yearly'!D94 -> 8061833.3 | D5: ='Financials Yearly'!E94 -> 11427056 | E5: ='Financials Yearly'!F94 -> 12253119 | F5: ='Financials Yearly'!G94 -> 13138898 | G5: ='Financials Yearly'!H94 -> 14088710 | H5: ='Financials Yearly'!I94 -> 15107184 | ... X5: ='Financials Yearly'!Y94 -> 0
A7: ='Financials Yearly'!B87 -> Cashflow Statement
B8: =B1 -> 2026 | C8: =C1 -> 2027 | D8: =D1 -> 2028 | E8: =E1 -> 2029 | F8: =F1 -> 2030 | G8: =G1 -> 2031 | H8: =H1 -> 2032 | I8: =I1 -> 2033 | ... X8: =X1 -> 2048
A9: ='Financials Yearly'!B88 -> Net Income | B9: ='Financials Yearly'!C88 -> -13468123 | C9: ='Financials Yearly'!D88 -> -16090608 | D9: ='Financials Yearly'!E88 -> 7219852.4 | E9: ='Financials Yearly'!F88 -> 16491830 | F9: ='Financials Yearly'!G88 -> 19586016 | G9: ='Financials Yearly'!H88 -> 21882079 | H9: ='Financials Yearly'!I88 -> 24522970 | ... X9: ='Financials Yearly'!Y88 -> 75741761
A10: ='Financials Yearly'!B89 -> Depreciation | B10: ='Financials Yearly'!C89 -> 0 | C10: ='Financials Yearly'!D89 -> 27292295 | D10: ='Financials Yearly'!E89 -> 36389726 | E10: ='Financials Yearly'!F89 -> 36389726 | F10: ='Financials Yearly'!G89 -> 36389726 | G10: ='Financials Yearly'!H89 -> 36389726 | H10: ='Financials Yearly'!I89 -> 36389726 | ... X10: ='Financials Yearly'!Y89 -> 1000000
A11: ='Financials Yearly'!B90 -> Amortization | B11: ='Financials Yearly'!C90 -> 0 | C11: ='Financials Yearly'!D90 -> 1834042.2 | D11: ='Financials Yearly'!E90 -> 203782.47 | E11: ='Financials Yearly'!F90 -> 203782.47 | F11: ='Financials Yearly'!G90 -> 203782.47 | G11: ='Financials Yearly'!H90 -> 203782.47 | H11: ='Financials Yearly'!I90 -> 203782.47 | ... X11: ='Financials Yearly'!Y90 -> 203782.47
A12: ='Financials Yearly'!B91 -> Net Cashflow from Operating Activities | B12: ='Financials Yearly'!C91 -> -13468123 | C12: ='Financials Yearly'!D91 -> 13035729 | D12: ='Financials Yearly'!E91 -> 43813361 | E12: ='Financials Yearly'!F91 -> 53085338 | F12: ='Financials Yearly'!G91 -> 56179524 | G12: ='Financials Yearly'!H91 -> 58475588 | H12: ='Financials Yearly'!I91 -> 61116479 | ... X12: ='Financials Yearly'!Y91 -> 76945544
A14: Revenue / Expense and Mortgage
B15: =B8 -> 2026 | C15: =C8 -> 2027 | D15: =D8 -> 2028 | E15: =E8 -> 2029 | F15: =F8 -> 2030 | G15: =G8 -> 2031 | H15: =H8 -> 2032 | I15: =I8 -> 2033 | ... X15: =X8 -> 2048
A16: =A2 -> Total Revenue | B16: =B2 -> 0 | C16: =C2 -> 42079158 | D16: =D2 -> 73261683 | E16: =E2 -> 79804722 | F16: =F2 -> 81225242 | G16: =G2 -> 82228620 | H16: =H2 -> 83477384 | ... X16: =X2 -> 1.072573e+08
A17: Expense and Mortgage | B17: =SUM(B3+B4+B5) -> 13468123 | C17: =SUM(C3+C4+C5) -> 37105262 | D17: =SUM(D3+D4+D5) -> 40875378 | E17: =SUM(E3+E4+E5) -> 38972502 | F17: =SUM(F3+F4+F5) -> 38184615 | G17: =SUM(G3+G4+G5) -> 37841742 | H17: =SUM(H3+H4+H5) -> 37468089 | I17: =SUM(I3+I4+I5) -> 37061343 | ... X17: =SUM(X3+X4+X5) -> 11376319
A18: Mortgage line 1.3 times | B18: =SUM(B17*1.3) -> 17508560 | C18: =SUM(C17*1.3) -> 48236841 | D18: =SUM(D17*1.3) -> 53137991 | E18: =SUM(E17*1.3) -> 50664253 | F18: =SUM(F17*1.3) -> 49640000 | G18: =SUM(G17*1.3) -> 49194265 | H18: =SUM(H17*1.3) -> 48708516 | I18: =SUM(I17*1.3) -> 48179745 | ... X18: =SUM(X17*1.3) -> 14789214
A20: Total Revenue and Expense | B20: =B1 -> 2026 | C20: =C1 -> 2027 | D20: =D1 -> 2028 | E20: =E1 -> 2029 | F20: =F1 -> 2030 | G20: =G1 -> 2031 | H20: =H1 -> 2032 | I20: =I1 -> 2033 | ... X20: =X1 -> 2048
A21: =A2 -> Total Revenue | B21: =B2 -> 0 | C21: =C2 -> 42079158 | D21: =D2 -> 73261683 | E21: =E2 -> 79804722 | F21: =F2 -> 81225242 | G21: =G2 -> 82228620 | H21: =H2 -> 83477384 | ... X21: =X2 -> 1.072573e+08
A22: Total Expense | B22: =SUM(B3:B5) -> 13468123 | C22: =SUM(C3:C5) -> 37105262 | D22: =SUM(D3:D5) -> 40875378 | E22: =SUM(E3:E5) -> 38972502 | F22: =SUM(F3:F5) -> 38184615 | G22: =SUM(G3:G5) -> 37841742 | H22: =SUM(H3:H5) -> 37468089 | I22: =SUM(I3:I5) -> 37061343 | ... X22: =SUM(X3:X5) -> 11376319
A23: Loan Ratio | B23: =SUM(B22 * 1.3) -> 17508560 | C23: =SUM(C22 * 1.3) -> 48236841 | D23: =SUM(D22 * 1.3) -> 53137991 | E23: =SUM(E22 * 1.3) -> 50664253 | F23: =SUM(F22 * 1.3) -> 49640000 | G23: =SUM(G22 * 1.3) -> 49194265 | H23: =SUM(H22 * 1.3) -> 48708516 | I23: =SUM(I22 * 1.3) -> 48179745 | ... X23: =SUM(X22 * 1.3) -> 14789214
A26: Revenue breakout | B26: =B20 -> 2026 | C26: =C20 -> 2027 | D26: =D20 -> 2028 | E26: =E20 -> 2029 | F26: =F20 -> 2030 | G26: =G20 -> 2031 | H26: =H20 -> 2032 | I26: =I20 -> 2033 | ... X26: =X20 -> 2048
A27: Core Revenue (Electrical and Fuel) | B27: =SUM('Financials Yearly'!C5+'Financials Yearly'!C16+'Financials Yearly'!C17+'Financials Yearly'!C18+'Financials Yearly'!C19+'Financials Yearly'!C20) -> 0 | C27: =SUM('Financials Yearly'!D5+'Financials Yearly'!D16+'Financials Yearly'!D17+'Financials Yearly'!D18+'Financials Yearly'!D19+'Financials Yearly'!D20) -> 0 | D27: =SUM('Financials Yearly'!E5+'Financials Yearly'!E16+'Financials Yearly'!E17+'Financials Yearly'!E18+'Financials Yearly'!E19+'Financials Yearly'!E20) -> 16398976 | E27: =SUM('Financials Yearly'!F5+'Financials Yearly'!F16+'Financials Yearly'!F17+'Financials Yearly'!F18+'Financials Yearly'!F19+'Financials Yearly'!F20) -> 21765914 | F27: =SUM('Financials Yearly'!G5+'Financials Yearly'!G16+'Financials Yearly'!G17+'Financials Yearly'!G18+'Financials Yearly'!G19+'Financials Yearly'!G20) -> 21825546 | G27: =SUM('Financials Yearly'!H5+'Financials Yearly'!H16+'Financials Yearly'!H17+'Financials Yearly'!H18+'Financials Yearly'!H19+'Financials Yearly'!H20) -> 21765914 | H27: =SUM('Financials Yearly'!I5+'Financials Yearly'!I16+'Financials Yearly'!I17+'Financials Yearly'!I18+'Financials Yearly'!I19+'Financials Yearly'!I20) -> 21765914 | I27: =SUM('Financials Yearly'!J5+'Financials Yearly'!J16+'Financials Yearly'!J17+'Financials Yearly'!J18+'Financials Yearly'!J19+'Financials Yearly'!J20) -> 21765914 | ... X27: =SUM('Financials Yearly'!Y5+'Financials Yearly'!Y16+'Financials Yearly'!Y17+'Financials Yearly'!Y18+'Financials Yearly'!Y19+'Financials Yearly'!Y20) -> 21765914
A28: Commodities (adjusted at 75% of value) | B28: =SUM('Financials Yearly'!C7+'Financials Yearly'!C8+'Financials Yearly'!C9+'Financials Yearly'!C10+'Financials Yearly'!C11+'Financials Yearly'!C12+'Financials Yearly'!C13) * 0.75 -> 0 | C28: =SUM('Financials Yearly'!D7+'Financials Yearly'!D8+'Financials Yearly'!D9+'Financials Yearly'!D10+'Financials Yearly'!D11+'Financials Yearly'!D12+'Financials Yearly'!D13) * 0.75 -> 21774744 | D28: =SUM('Financials Yearly'!E7+'Financials Yearly'!E8+'Financials Yearly'!E9+'Financials Yearly'!E10+'Financials Yearly'!E11+'Financials Yearly'!E12+'Financials Yearly'!E13) * 0.75 -> 29411946 | E28: =SUM('Financials Yearly'!F7+'Financials Yearly'!F8+'Financials Yearly'!F9+'Financials Yearly'!F10+'Financials Yearly'!F11+'Financials Yearly'!F12+'Financials Yearly'!F13) * 0.75 -> 30005607 | F28: =SUM('Financials Yearly'!G7+'Financials Yearly'!G8+'Financials Yearly'!G9+'Financials Yearly'!G10+'Financials Yearly'!G11+'Financials Yearly'!G12+'Financials Yearly'!G13) * 0.75 -> 30694486 | G28: =SUM('Financials Yearly'!H7+'Financials Yearly'!H8+'Financials Yearly'!H9+'Financials Yearly'!H10+'Financials Yearly'!H11+'Financials Yearly'!H12+'Financials Yearly'!H13) * 0.75 -> 31229120 | H28: =SUM('Financials Yearly'!I7+'Financials Yearly'!I8+'Financials Yearly'!I9+'Financials Yearly'!I10+'Financials Yearly'!I11+'Financials Yearly'!I12+'Financials Yearly'!I13) * 0.75 -> 31859459 | I28: =SUM('Financials Yearly'!J7+'Financials Yearly'!J8+'Financials Yearly'!J9+'Financials Yearly'!J10+'Financials Yearly'!J11+'Financials Yearly'!J12+'Financials Yearly'!J13) * 0.75 -> 32502522 | ... X28: =SUM('Financials Yearly'!Y7+'Financials Yearly'!Y8+'Financials Yearly'!Y9+'Financials Yearly'!Y10+'Financials Yearly'!Y11+'Financials Yearly'!Y12+'Financials Yearly'!Y13) * 0.75 -> 43862860
A30: =A27 -> Core Revenue (Electrical and Fuel) | B30: =SUM(B27:X27) -> 4.5177688e+08
A31: =A28 -> Commodities (adjusted at 75% of value) | B31: =SUM(B28:X28) -> 7.8166712e+08
A33: Core Revenue to Expense | B33: =B26 -> 2026 | C33: =C26 -> 2027 | D33: =D26 -> 2028 | E33: =E26 -> 2029 | F33: =F26 -> 2030 | G33: =G26 -> 2031 | H33: =H26 -> 2032 | I33: =I26 -> 2033 | ... X33: =X26 -> 2048
A34: =A27 -> Core Revenue (Electrical and Fuel) | B34: =B27 -> 0 | C34: =C27 -> 0 | D34: =D27 -> 16398976 | E34: =E27 -> 21765914 | F34: =F27 -> 21825546 | G34: =G27 -> 21765914 | H34: =H27 -> 21765914 | ... X34: =X27 -> 21765914
A35: =A22 -> Total Expense | B35: =B17 -> 13468123 | C35: =C17 -> 37105262 | D35: =D17 -> 40875378 | E35: =E17 -> 38972502 | F35: =F17 -> 38184615 | G35: =G17 -> 37841742 | H35: =H17 -> 37468089 | I35: =I17 -> 37061343 | ... X35: =X17 -> 11376319
A36: =A23 -> Loan Ratio | B36: =SUM(B35 * 1.3) -> 17508560 | C36: =SUM(C35 * 1.3) -> 48236841 | D36: =SUM(D35 * 1.3) -> 53137991 | E36: =SUM(E35 * 1.3) -> 50664253 | F36: =SUM(F35 * 1.3) -> 49640000 | G36: =SUM(G35 * 1.3) -> 49194265 | H36: =SUM(H35 * 1.3) -> 48708516 | I36: =SUM(I35 * 1.3) -> 48179745 | ... X36: =SUM(X35 * 1.3) -> 14789214
B38: =B33 -> 2026 | C38: =C33 -> 2027 | D38: =D33 -> 2028 | E38: =E33 -> 2029 | F38: =F33 -> 2030 | G38: =G33 -> 2031 | H38: =H33 -> 2032 | I38: =I33 -> 2033 | ... X38: =X33 -> 2048
A39: Revenue | B39: =B2 -> 0 | C39: =C2 -> 42079158 | D39: =D2 -> 73261683 | E39: =E2 -> 79804722 | F39: =F2 -> 81225242 | G39: =G2 -> 82228620 | H39: =H2 -> 83477384 | I39: =I2 -> 84751355 | ... X39: =X2 -> 1.072573e+08
A40: ='Financials Yearly'!B51 -> EBITDA | B40: ='Financials Yearly'!C51 -> -4213882 | C40: ='Financials Yearly'!D51 -> 27575573 | D40: ='Financials Yearly'!E51 -> 56659882 | E40: ='Financials Yearly'!F51 -> 64973638 | F40: ='Financials Yearly'!G51 -> 67182045 | G40: ='Financials Yearly'!H51 -> 68528296 | H40: ='Financials Yearly'!I51 -> 70150714 | ... X40: ='Financials Yearly'!Y51 -> 95880984
A42: These graphs are based on the full 25 year projections
A44: Revenue Stream Breakout | J44: =A45 -> Income Power | K44: =B45 -> 21765914
A45: ='Financials Yearly'!B5 -> Income Power | B45: ='Financials Yearly'!O5 -> 21765914 | J45: ='Financials Yearly'!B7 -> Activated Carbon Ash | K45: ='Financials Yearly'!F7 -> 16233629
A46: ='Financials Yearly'!B7 -> Activated Carbon Ash | B46: ='Financials Yearly'!O7 -> 19432271 | J46: =A52 -> Carbon Black | K46: =B52 -> 10340590
A47: ='Financials Yearly'!B8 -> Aluminum | B47: ='Financials Yearly'!O8 -> 4333307.1 | J47: =A53 -> Graphene | K47: =B53 -> 23266327
A48: ='Financials Yearly'!B9 -> Ferrous Metals | B48: ='Financials Yearly'!O9 -> 560594.76 | J48: Ferrous and non-ferrous metals | K48: =SUM('Financials Yearly'!F8:F10) -> 13775733
A49: ='Financials Yearly'!B10 -> Non-Ferrous Metals | B49: ='Financials Yearly'!O10 -> 11596174 | J49: Steel | K49: =SUM('Financials Yearly'!F11:F12) -> 1359633.7
A50: ='Financials Yearly'!B11 -> Steel from Tires | B50: ='Financials Yearly'!O11 -> 1627533.2
...

Sheet Summary
B2: Sources | D2: $USD | E2: % | G2: Uses | I2: $USD | J2: % | M2: ='Data Sources'!C1 -> 2026 | N2: =M2+1 -> 2027 | O2: =N2+1 -> 2028 | P2: =O2+1 -> 2029 | Q2: =P2+1 -> 2030 | R2: =Q2+1 -> 2031 | S2: =R2+1 -> 2032 | T2: =S2+1 -> 2033 | U2: =T2+1 -> 2034 | ... AI2: =AH2+1 -> 2048
B3: Equity | D3: =D8-SUM(D4:D5) -> 64955662 | E3: =D3/$D$8 -> 0.23774314 | G3: Capital Expenditures | I3: =CapEx!$D$113 -> 2.5472808e+08 | J3: =I3/$I$7 -> 0.93232606 | L3: Revenue | M3: =SUMIF(Financials!$C$6:$JR$6,Summary!M$2,Financials!$C$37:$JR$37) -> 0 | N3: =SUMIF(Financials!$C$6:$JR$6,Summary!N$2,Financials!$C$37:$JR$37) -> 42079158 | O3: =SUMIF(Financials!$C$6:$JR$6,Summary!O$2,Financials!$C$37:$JR$37) -> 73261683 | P3: =SUMIF(Financials!$C$6:$JR$6,Summary!P$2,Financials!$C$37:$JR$37) -> 79804722 | Q3: =SUMIF(Financials!$C$6:$JR$6,Summary!Q$2,Financials!$C$37:$JR$37) -> 81225242 | R3: =SUMIF(Financials!$C$6:$JR$6,Summary!R$2,Financials!$C$37:$JR$37) -> 82228620 | S3: =SUMIF(Financials!$C$6:$JR$6,Summary!S$2,Financials!$C$37:$JR$37) -> 83477384 | T3: =SUMIF(Financials!$C$6:$JR$6,Summary!T$2,Financials!$C$37:$JR$37) -> 84751355 | ... AI3: =SUMIF(Financials!$C$6:$JR$6,Summary!AI$2,Financials!$C$37:$JR$37) -> 1.072573e+08
B4: DSRA | D4: =$I$6 -> 13395165 | E4: =D4/$D$8 -> 0.049027421 | G4: CREC Engineering Oversight | H4: 0.01 | I4: =H4*$I$3 -> 2547280.8 | J4: =I4/$I$7 -> 0.0093232606 | L4: Expenses | M4: =SUMIF(Financials!$C$6:$JR$6,Summary!M$2,Financials!$C$56:$JR$56) -> 7223797.8 | N4: =SUMIF(Financials!$C$6:$JR$6,Summary!N$2,Financials!$C$56:$JR$56) -> 14503585 | O4: =SUMIF(Financials!$C$6:$JR$6,Summary!O$2,Financials!$C$56:$JR$56) -> 16601801 | P4: =SUMIF(Financials!$C$6:$JR$6,Summary!P$2,Financials!$C$56:$JR$56) -> 14831084 | Q4: =SUMIF(Financials!$C$6:$JR$6,Summary!Q$2,Financials!$C$56:$JR$56) -> 14043197 | R4: =SUMIF(Financials!$C$6:$JR$6,Summary!R$2,Financials!$C$56:$JR$56) -> 13700323 | S4: =SUMIF(Financials!$C$6:$JR$6,Summary!S$2,Financials!$C$56:$JR$56) -> 13326671 | T4: =SUMIF(Financials!$C$6:$JR$6,Summary!T$2,Financials!$C$56:$JR$56) -> 12919924 | ... AI4: =SUMIF(Financials!$C$6:$JR$6,Summary!AI$2,Financials!$C$56:$JR$56) -> 11376319
B5: Debt | C5: 0.75 | D5: =SUM($I$3:$I$5)*$C$5 -> 1.9486698e+08 | E5: =D5/$D$8 -> 0.71322943 | G5: Transaction Expenses | H5: 0.01 | I5: =H5*SUM($I$3) -> 2547280.8 | J5: =I5/$I$7 -> 0.0093232606 | L5: EBITDA | M5: =SUMIF(Financials!$C$6:$JR$6,Summary!M$2,Financials!$C$58:$JR$58) -> -7223797.8 | N5: =SUMIF(Financials!$C$6:$JR$6,Summary!N$2,Financials!$C$58:$JR$58) -> 27575573 | O5: =SUMIF(Financials!$C$6:$JR$6,Summary!O$2,Financials!$C$58:$JR$58) -> 56659882 | P5: =SUMIF(Financials!$C$6:$JR$6,Summary!P$2,Financials!$C$58:$JR$58) -> 64973638 | Q5: =SUMIF(Financials!$C$6:$JR$6,Summary!Q$2,Financials!$C$58:$JR$58) -> 67182045 | R5: =SUMIF(Financials!$C$6:$JR$6,Summary!R$2,Financials!$C$58:$JR$58) -> 68528296 | S5: =SUMIF(Financials!$C$6:$JR$6,Summary!S$2,Financials!$C$58:$JR$58) -> 70150714 | T5: =SUMIF(Financials!$C$6:$JR$6,Summary!T$2,Financials!$C$58:$JR$58) -> 71831431 | ... AI5: =SUMIF(Financials!$C$6:$JR$6,Summary!AI$2,Financials!$C$58:$JR$58) -> 95880984
G6: {='Capital Contributions'!A6:B6} -> Construction Loan | H6: 0 | I6: =SUM('Capital Contributions'!$E$10:$JT$10) -> 13395165 | J6: =I6/$I$7 -> 0.049027421
G7: Total | I7: =SUM(I3:I6) -> 2.7321781e+08 | J7: =SUM(J3:J6) -> 1 | L7: Interest Expense | M7: =-SUMIF(Financials!$C$6:$JR$6,Summary!M$2,Financials!$C$70:$JR$70) -> -9254241.3 | N7: =-SUMIF(Financials!$C$6:$JR$6,Summary!N$2,Financials!$C$70:$JR$70) -> -14185154 | O7: =-SUMIF(Financials!$C$6:$JR$6,Summary!O$2,Financials!$C$70:$JR$70) -> -12714362 | P7: =-SUMIF(Financials!$C$6:$JR$6,Summary!P$2,Financials!$C$70:$JR$70) -> -11888300 | Q7: =-SUMIF(Financials!$C$6:$JR$6,Summary!Q$2,Financials!$C$70:$JR$70) -> -11002521 | R7: =-SUMIF(Financials!$C$6:$JR$6,Summary!R$2,Financials!$C$70:$JR$70) -> -10052709 | S7: =-SUMIF(Financials!$C$6:$JR$6,Summary!S$2,Financials!$C$70:$JR$70) -> -9034234.5 | T7: =-SUMIF(Financials!$C$6:$JR$6,Summary!T$2,Financials!$C$70:$JR$70) -> -7942135 | ... AI7: =-SUMIF(Financials!$C$6:$JR$6,Summary!AI$2,Financials!$C$70:$JR$70) -> 0
B8: Total | D8: =I7 -> 2.7321781e+08 | E8: =SUM(E3:E7) -> 1 | L8: Depreciation & Amortization | M8: =-SUMIF(Financials!$C$6:$JR$6,Summary!M$2,Financials!$C$66:$JR$66) -> 0 | N8: =-SUMIF(Financials!$C$6:$JR$6,Summary!N$2,Financials!$C$66:$JR$66) -> -29126337 | O8: =-SUMIF(Financials!$C$6:$JR$6,Summary!O$2,Financials!$C$66:$JR$66) -> -36593509 | P8: =-SUMIF(Financials!$C$6:$JR$6,Summary!P$2,Financials!$C$66:$JR$66) -> -36593509 | Q8: =-SUMIF(Financials!$C$6:$JR$6,Summary!Q$2,Financials!$C$66:$JR$66) -> -36593509 | R8: =-SUMIF(Financials!$C$6:$JR$6,Summary!R$2,Financials!$C$66:$JR$66) -> -36593509 | S8: =-SUMIF(Financials!$C$6:$JR$6,Summary!S$2,Financials!$C$66:$JR$66) -> -36593509 | T8: =-SUMIF(Financials!$C$6:$JR$6,Summary!T$2,Financials!$C$66:$JR$66) -> -36736366 | ... AI8: =-SUMIF(Financials!$C$6:$JR$6,Summary!AI$2,Financials!$C$66:$JR$66) -> -1203782.5
L9: Taxes | M9: =-SUMIF(Financials!$C$6:$JR$6,Summary!M$2,Financials!$C$89:$JR$89) -> 0 | N9: =-SUMIF(Financials!$C$6:$JR$6,Summary!N$2,Financials!$C$89:$JR$89) -> 0 | O9: =-SUMIF(Financials!$C$6:$JR$6,Summary!O$2,Financials!$C$89:$JR$89) -> 0 | P9: =-SUMIF(Financials!$C$6:$JR$6,Summary!P$2,Financials!$C$89:$JR$89) -> 0 | Q9: =-SUMIF(Financials!$C$6:$JR$6,Summary!Q$2,Financials!$C$89:$JR$89) -> 0 | R9: =-SUMIF(Financials!$C$6:$JR$6,Summary!R$2,Financials!$C$89:$JR$89) -> 0 | S9: =-SUMIF(Financials!$C$6:$JR$6,Summary!S$2,Financials!$C$89:$JR$89) -> 0 | T9: =-SUMIF(Financials!$C$6:$JR$6,Summary!T$2,Financials!$C$89:$JR$89) -> 0 | ... AI9: =-SUMIF(Financials!$C$6:$JR$6,Summary!AI$2,Financials!$C$89:$JR$89) -> -18935440
G10: Total Equity Contributed | H10: =-SUM('NPV IRR'!C5:JR5) -> 78350826 | L10: Net Income | M10: =SUM(M5:M9) -> -16478039 | N10: =SUM(N5:N9) -> -15735918 | O10: =SUM(O5:O9) -> 7352010.6 | P10: =SUM(P5:P9) -> 16491830 | Q10: =SUM(Q5:Q9) -> 19586016 | R10: =SUM(R5:R9) -> 21882079 | S10: =SUM(S5:S9) -> 24522970 | T10: =SUM(T5:T9) -> 27152930 | ... AI10: =SUM(AI5:AI9) -> 75741761
B11: Initial Construction Interest-Only Loan | G11: Total Project Cash Flow | H11: =SUM('NPV IRR'!C6:JR6) -> 1.1293807e+09
B12: Loan-to-Value | C12: ='Capital Contributions'!B7 -> 0.71322943 | G12: Total Project Equity IRR % | H12: ='NPV IRR'!$B$10 -> 0.39179596 | M12: =M2 -> 2026 | N12: =M12+1 -> 2027 | O12: =N12+1 -> 2028 | P12: =O12+1 -> 2029 | Q12: =P12+1 -> 2030 | R12: =Q12+1 -> 2031 | S12: =R12+1 -> 2032 | T12: =S12+1 -> 2033 | U12: =T12+1 -> 2034 | ... AI12: =AH12+1 -> 2048
B13: Amount | C13: ='Capital Contributions'!B8 -> 1.9486698e+08 | G13: Net Present Value | H13: ='NPV IRR'!$B$22 -> 2.3306971e+08 | L13: Equity Contributions | M13: =SUMIF('NPV IRR'!$C$3:$JR$3,Summary!M$12,'NPV IRR'!$C$5:$JR$5) -> -74209903 | N13: =SUMIF('NPV IRR'!$C$3:$JR$3,Summary!N$12,'NPV IRR'!$C$5:$JR$5) -> -4140923.4 | O13: =SUMIF('NPV IRR'!$C$3:$JR$3,Summary!O$12,'NPV IRR'!$C$5:$JR$5) -> 0 | P13: =SUMIF('NPV IRR'!$C$3:$JR$3,Summary!P$12,'NPV IRR'!$C$5:$JR$5) -> 0 | Q13: =SUMIF('NPV IRR'!$C$3:$JR$3,Summary!Q$12,'NPV IRR'!$C$5:$JR$5) -> 0 | R13: =SUMIF('NPV IRR'!$C$3:$JR$3,Summary!R$12,'NPV IRR'!$C$5:$JR$5) -> 0 | S13: =SUMIF('NPV IRR'!$C$3:$JR$3,Summary!S$12,'NPV IRR'!$C$5:$JR$5) -> 0 | T13: =SUMIF('NPV IRR'!$C$3:$JR$3,Summary!T$12,'NPV IRR'!$C$5:$JR$5) -> 0 | ... AI13: =SUMIF('NPV IRR'!$C$3:$JR$3,Summary!AI$12,'NPV IRR'!$C$5:$JR$5) -> 0
B14: Interest Rate | C14: ='Capital Contributions'!B9 -> 0.085 | G14: Total Project IRR % | H14: ='NPV IRR'!$B$36 -> 0.205466 | L14: Debt Amortization Payment | M14: =SUMIF(Financials!$C$6:$JR$6,Summary!M$12,Financials!$C$101:$JR$101) -> 0 | N14: =SUMIF(Financials!$C$6:$JR$6,Summary!N$12,Financials!$C$101:$JR$101) -> 8061833.3 | O14: =SUMIF(Financials!$C$6:$JR$6,Summary!O$12,Financials!$C$101:$JR$101) -> 11427056 | P14: =SUMIF(Financials!$C$6:$JR$6,Summary!P$12,Financials!$C$101:$JR$101) -> 12253119 | Q14: =SUMIF(Financials!$C$6:$JR$6,Summary!Q$12,Financials!$C$101:$JR$101) -> 13138898 | R14: =SUMIF(Financials!$C$6:$JR$6,Summary!R$12,Financials!$C$101:$JR$101) -> 14088710 | S14: =SUMIF(Financials!$C$6:$JR$6,Summary!S$12,Financials!$C$101:$JR$101) -> 15107184 | T14: =SUMIF(Financials!$C$6:$JR$6,Summary!T$12,Financials!$C$101:$JR$101) -> 16199284 | ... AI14: =SUMIF(Financials!$C$6:$JR$6,Summary!AI$12,Financials!$C$101:$JR$101) -> 0
B15: Term | C15: ='Capital Contributions'!B10 -> COD | L15: Capital Expenditures | M15: =SUMIF(Financials!$C$6:$JR$6,Summary!M2,Financials!$C$100:$JR$100) -> 0 | N15: =SUMIF(Financials!$C$6:$JR$6,Summary!N2,Financials!$C$100:$JR$100) -> 0 | O15: =SUMIF(Financials!$C$6:$JR$6,Summary!O2,Financials!$C$100:$JR$100) -> 0 | P15: =SUMIF(Financials!$C$6:$JR$6,Summary!P2,Financials!$C$100:$JR$100) -> 0 | Q15: =SUMIF(Financials!$C$6:$JR$6,Summary!Q2,Financials!$C$100:$JR$100) -> 0 | R15: =SUMIF(Financials!$C$6:$JR$6,Summary!R2,Financials!$C$100:$JR$100) -> 0 | S15: =SUMIF(Financials!$C$6:$JR$6,Summary!S2,Financials!$C$100:$JR$100) -> 0 | T15: =SUMIF(Financials!$C$6:$JR$6,Summary!T2,Financials!$C$100:$JR$100) -> 1000000 | ... AI15: =SUMIF(Financials!$C$6:$JR$6,Summary!AI2,Financials!$C$100:$JR$100) -> 1000000
B16: Interest-Only | C16: ='Capital Contributions'!B11 -> Yes | L16: Project Cash Flow | M16: =SUMIF('NPV IRR'!$C$3:$JR$3,Summary!M$12,'NPV IRR'!$C$6:$JR$6) -> 0 | N16: =SUMIF('NPV IRR'!$C$3:$JR$3,Summary!N$12,'NPV IRR'!$C$6:$JR$6) -> 10779995 | O16: =SUMIF('NPV IRR'!$C$3:$JR$3,Summary!O$12,'NPV IRR'!$C$6:$JR$6) -> 30892540 | P16: =SUMIF('NPV IRR'!$C$3:$JR$3,Summary!P$12,'NPV IRR'!$C$6:$JR$6) -> 38790608 | Q16: =SUMIF('NPV IRR'!$C$3:$JR$3,Summary!Q$12,'NPV IRR'!$C$6:$JR$6) -> 40888595 | R16: =SUMIF('NPV IRR'!$C$3:$JR$3,Summary!R$12,'NPV IRR'!$C$6:$JR$6) -> 42167534 | S16: =SUMIF('NPV IRR'!$C$3:$JR$3,Summary!S$12,'NPV IRR'!$C$6:$JR$6) -> 43708830 | T16: =SUMIF('NPV IRR'!$C$3:$JR$3,Summary!T$12,'NPV IRR'!$C$6:$JR$6) -> 44355512 | ... AI16: =SUMIF('NPV IRR'!$C$3:$JR$3,Summary!AI$12,'NPV IRR'!$C$6:$JR$6) -> 75945544
B18: Refinance - Term Loan
B19: Month | C19: ='Capital Contributions'!B14 -> 16
B20: Loan-to-Value | C20: ='Capital Contributions'!B15 -> 0.35
B21: Amount | C21: ='Capital Contributions'!B16 -> 95626234
B22: Interest Rate | C22: ='Capital Contributions'!B17 -> 0.07 | L22: 20 Year Cash Flow $mm
B23: Term | C23: ='Capital Contributions'!B18 -> 15 | L23: EBITDA | M23: =SUM($M$5:$AI$5) -> 1.6952971e+09
B24: Final Month | C24: ='Capital Contributions'!B19 -> 196 | L24: Project Cash Flow | M24: =SUM($M$16:$AI$16) -> 1.1293807e+09
B26: Refinance - High Yield Loan | L26: ($USD in millions) | M26: =M2+2 -> 2028 | N26: =M26+1 -> 2029 | O26: =N26+1 -> 2030 | P26: =O26+1 -> 2031 | Q26: =P26+1 -> 2032 | R26: =Q26+1 -> 2033 | S26: =R26+1 -> 2034 | T26: =S26+1 -> 2035 | U26: =T26+1 -> 2036 | ... AG26: =AF26+1 -> 2048
B27: Month | C27: ='Capital Contributions'!B22 -> 16 | L27: Revenue
B28: Loan-to-Value | C28: ='Capital Contributions'!B23 -> 0.36322943 | L28: Power Sales | M28: =SUMIF(Financials!$C$6:$JR$6,Summary!M$26,Financials!$C$12:$JR$12) -> 16398976 | N28: =SUMIF(Financials!$C$6:$JR$6,Summary!N$26,Financials!$C$12:$JR$12) -> 21765914 | O28: =SUMIF(Financials!$C$6:$JR$6,Summary!O$26,Financials!$C$12:$JR$12) -> 21825546 | P28: =SUMIF(Financials!$C$6:$JR$6,Summary!P$26,Financials!$C$12:$JR$12) -> 21765914 | Q28: =SUMIF(Financials!$C$6:$JR$6,Summary!Q$26,Financials!$C$12:$JR$12) -> 21765914 | R28: =SUMIF(Financials!$C$6:$JR$6,Summary!R$26,Financials!$C$12:$JR$12) -> 21765914 | S28: =SUMIF(Financials!$C$6:$JR$6,Summary!S$26,Financials!$C$12:$JR$12) -> 21765914 | T28: =SUMIF(Financials!$C$6:$JR$6,Summary!T$26,Financials!$C$12:$JR$12) -> 21765914 | ... AG28: =SUMIF(Financials!$C$6:$JR$6,Summary!AG$26,Financials!$C$12:$JR$12) -> 21765914
B29: Amount | C29: ='Capital Contributions'!B24 -> 99240751 | L29: Commodity Sales | M29: =SUMIF(Financials!$C$6:$JR$6,Summary!M$26,Financials!$C$28:$JR$28)-M28 -> 58267957 | N29: =SUMIF(Financials!$C$6:$JR$6,Summary!N$26,Financials!$C$28:$JR$28)-N28 -> 59444058 | O29: =SUMIF(Financials!$C$6:$JR$6,Summary!O$26,Financials!$C$28:$JR$28)-O28 -> 60808795 | P29: =SUMIF(Financials!$C$6:$JR$6,Summary!P$26,Financials!$C$28:$JR$28)-P28 -> 61867956 | Q29: =SUMIF(Financials!$C$6:$JR$6,Summary!Q$26,Financials!$C$28:$JR$28)-Q28 -> 63116721 | R29: =SUMIF(Financials!$C$6:$JR$6,Summary!R$26,Financials!$C$28:$JR$28)-R28 -> 64390691 | S29: =SUMIF(Financials!$C$6:$JR$6,Summary!S$26,Financials!$C$28:$JR$28)-S28 -> 65690376 | T29: =SUMIF(Financials!$C$6:$JR$6,Summary!T$26,Financials!$C$28:$JR$28)-T28 -> 67016294 | ... AG29: =SUMIF(Financials!$C$6:$JR$6,Summary!AG$26,Financials!$C$28:$JR$28)-AG28 -> 86896639
B30: Interest Rate | C30: ='Capital Contributions'!B25 -> 0.07 | L30: Byproduct Sales | M30: =SUMIF(Financials!$C$6:$JR$6,Summary!M$26,Financials!$C$35:$JR$35) -> -1405250 | N30: =SUMIF(Financials!$C$6:$JR$6,Summary!N$26,Financials!$C$35:$JR$35) -> -1405250 | O30: =SUMIF(Financials!$C$6:$JR$6,Summary!O$26,Financials!$C$35:$JR$35) -> -1409100 | P30: =SUMIF(Financials!$C$6:$JR$6,Summary!P$26,Financials!$C$35:$JR$35) -> -1405250 | Q30: =SUMIF(Financials!$C$6:$JR$6,Summary!Q$26,Financials!$C$35:$JR$35) -> -1405250 | R30: =SUMIF(Financials!$C$6:$JR$6,Summary!R$26,Financials!$C$35:$JR$35) -> -1405250 | S30: =SUMIF(Financials!$C$6:$JR$6,Summary!S$26,Financials!$C$35:$JR$35) -> -1405250 | T30: =SUMIF(Financials!$C$6:$JR$6,Summary!T$26,Financials!$C$35:$JR$35) -> -1405250 | ... AG30: =SUMIF(Financials!$C$6:$JR$6,Summary!AG$26,Financials!$C$35:$JR$35) -> -1405250
B31: Term | C31: ='Capital Contributions'!B26 -> 10 | L31: Total Revenue | M31: =SUM(M28:M30) -> 73261683 | N31: =SUM(N28:N30) -> 79804722 | O31: =SUM(O28:O30) -> 81225242 | P31: =SUM(P28:P30) -> 82228620 | Q31: =SUM(Q28:Q30) -> 83477384 | R31: =SUM(R28:R30) -> 84751355 | S31: =SUM(S28:S30) -> 86051039 | T31: =SUM(T28:T30) -> 87376957 | ... AG31: =SUM(AG28:AG30) -> 1.072573e+08
B32: Final Month | C32: ='Capital Contributions'!B27 -> 136
L33: Total Expenses | M33: =SUMIF(Financials!$C$6:$JR$6,Summary!M$26,Financials!$C$56:$JR$56) -> 16601801 | N33: =SUMIF(Financials!$C$6:$JR$6,Summary!N$26,Financials!$C$56:$JR$56) -> 14831084 | O33: =SUMIF(Financials!$C$6:$JR$6,Summary!O$26,Financials!$C$56:$JR$56) -> 14043197 | P33: =SUMIF(Financials!$C$6:$JR$6,Summary!P$26,Financials!$C$56:$JR$56) -> 13700323 | Q33: =SUMIF(Financials!$C$6:$JR$6,Summary!Q$26,Financials!$C$56:$JR$56) -> 13326671 | R33: =SUMIF(Financials!$C$6:$JR$6,Summary!R$26,Financials!$C$56:$JR$56) -> 12919924 | S33: =SUMIF(Financials!$C$6:$JR$6,Summary!S$26,Financials!$C$56:$JR$56) -> 12477600 | T33: =SUMIF(Financials!$C$6:$JR$6,Summary!T$26,Financials!$C$56:$JR$56) -> 11997034 | ... AG33: =SUMIF(Financials!$C$6:$JR$6,Summary!AG$26,Financials!$C$56:$JR$56) -> 11376319
L34: % of Revenue | M34: =M33/M$31 -> 0.22660961 | N34: =N33/N$31 -> 0.18584218 | O34: =O33/O$31 -> 0.17289203 | P34: =P33/P$31 -> 0.16661259 | Q34: =Q33/Q$31 -> 0.15964408 | R34: =R33/R$31 -> 0.15244504 | S34: =S33/S$31 -> 0.14500231 | T34: =T33/T$31 -> 0.13730203 | ... AG34: =AG33/AG$31 -> 0.10606568
L36: EBITDA | M36: =HLOOKUP(M$26,$M$2:$AI$16,4,0) -> 56659882 | N36: =HLOOKUP(N$26,$M$2:$AI$16,4,0) -> 64973638 | O36: =HLOOKUP(O$26,$M$2:$AI$16,4,0) -> 67182045 | P36: =HLOOKUP(P$26,$M$2:$AI$16,4,0) -> 68528296 | Q36: =HLOOKUP(Q$26,$M$2:$AI$16,4,0) -> 70150714 | R36: =HLOOKUP(R$26,$M$2:$AI$16,4,0) -> 71831431 | S36: =HLOOKUP(S$26,$M$2:$AI$16,4,0) -> 73573440 | T36: =HLOOKUP(T$26,$M$2:$AI$16,4,0) -> 75379924 | ... AG36: =HLOOKUP(AG$26,$M$2:$AI$16,4,0) -> 95880984
L37: % Margin | M37: =M36/M31 -> 0.77339039 | N37: =N36/N31 -> 0.81415782 | O37: =O36/O31 -> 0.82710797 | P37: =P36/P31 -> 0.83338741 | Q37: =Q36/Q31 -> 0.84035592 | R37: =R36/R31 -> 0.84755496 | S37: =S36/S31 -> 0.85499769 | T37: =T36/T31 -> 0.86269797 | ... AG37: =AG36/AG31 -> 0.89393432
B39: Revenue Graphs | L39: Project Cash Flow | M39: =HLOOKUP(M$26,$M$2:$AI$16,15,0) -> 30892540 | N39: =HLOOKUP(N$26,$M$2:$AI$16,15,0) -> 38790608 | O39: =HLOOKUP(O$26,$M$2:$AI$16,15,0) -> 40888595 | P39: =HLOOKUP(P$26,$M$2:$AI$16,15,0) -> 42167534 | Q39: =HLOOKUP(Q$26,$M$2:$AI$16,15,0) -> 43708830 | R39: =HLOOKUP(R$26,$M$2:$AI$16,15,0) -> 44355512 | S39: =HLOOKUP(S$26,$M$2:$AI$16,15,0) -> 46010420 | T39: =HLOOKUP(T$26,$M$2:$AI$16,15,0) -> 46585282 | ... AG39: =HLOOKUP(AG$26,$M$2:$AI$16,15,0) -> 75945544
L40: % Margin | M40: =M39/M31 -> 0.42167391 | N40: =N39/N31 -> 0.48606909 | O40: =O39/O31 -> 0.50339764 | P40: =P39/P31 -> 0.51280848 | Q40: =Q39/Q31 -> 0.52360086 | R40: =R39/R31 -> 0.5233605 | S40: =S39/S31 -> 0.53468756 | T40: =T39/T31 -> 0.53315294 | ... AG40: =AG39/AG31 -> 0.70806875
B41: =Financials!B12 -> Income Power | C41: =Financials!AG12 -> 1848611.9
B42: =Financials!B13 -> RNG Sale price | C42: =Financials!AG13 -> 0
B43: =Financials!B14 -> Activated Carbon Ash | C43: =Financials!AG14 -> 1352512.9 | L43: Net Income | M43: =HLOOKUP(M$26,$M$2:$AI$10,9,0) -> 7352010.6 | N43: =HLOOKUP(N$26,$M$2:$AI$10,9,0) -> 16491830 | O43: =HLOOKUP(O$26,$M$2:$AI$10,9,0) -> 19586016 | P43: =HLOOKUP(P$26,$M$2:$AI$10,9,0) -> 21882079 | Q43: =HLOOKUP(Q$26,$M$2:$AI$10,9,0) -> 24522970 | R43: =HLOOKUP(R$26,$M$2:$AI$10,9,0) -> 27152930 | S43: =HLOOKUP(S$26,$M$2:$AI$10,9,0) -> 57215424 | T43: =HLOOKUP(T$26,$M$2:$AI$10,9,0) -> 68030818 | ... AG43: =HLOOKUP(AG$26,$M$2:$AI$10,9,0) -> 75741761
B44: =Financials!B15 -> Aluminum | C44: =Financials!AG15 -> 301604.16 | L44: % Margin | M44: =M43/M31 -> 0.10035274 | N44: =N43/N31 -> 0.2066523 | O44: =O43/O31 -> 0.24113213 | P44: =P43/P31 -> 0.26611269 | Q44: =Q43/Q31 -> 0.29376783 | R44: =R43/R31 -> 0.32038343 | S44: =S43/S31 -> 0.66490102 | T44: =T43/T31 -> 0.77858992 | ... AG44: =AG43/AG31 -> 0.70616881
B45: =Financials!B16 -> Ferrous Metals | C45: =Financials!AG16 -> 39018.17
...

Sheet Data Sources
A1: Year Financial Model starts | C1: 2026
A2: Month | C2: 1
A3: Day | C3: 30
A4: Month to get online | C4: 16 | E4: How long from start of construction to operations
A5: Metric Ton | C5: 2204.62
A6: Days in a year | C6: 365
A7: Technical Risk insurance | C7: 0.01 | E7: Technical risk policy guarantying the loan
A8: MIGA Debt insurance | C8: 0.022 | E8: Political risk policy guarantying the loan
A9: MIGA Equity insurance | C9: 0.02 | E9: Political risk policy guarantying the loan
A10: Days in year MSW received | B10: days | C10: 365 | E10: OVD delivers every day even on holidays
A11: Days in year tires received | B11: days | C11: 365 | E11: OVD delivers every day even on holidays
A12: 1 KiloCalorie = | B12: BTU | C12: 3.96567
A13: Stage 1 processing hours per day | B13: hours | C13: 19 | E13: The remaining hours are for maintenance on the stage 1 equipment
A14: Days for onsite storage | B14: days | C14: 7 | E14: for feedstock and byproducts
A15: Altitude of the REP | B15: feet | C15: 55 | E15: Altitudes of the Renewable Energy Park
A16: Percent Loss to conditioning gas | C16: 0.1
A17: Conditioning cost per MMBTU in USD | C17: 5
A18: Percent Aluminum in non ferrous metals | B18: % | C18: 0.6 | E18: Average in USA waste stream
A19: Desired Mwe goal | B19: Mwe | C19: 44 | E19: How much electricity do you desire
A20: Maintenance fund contribution | C20: 0.05 | E20: set aside for plant maintenance and equipment repair
A21: Max maintenance fund value | C21: 45000000 | E21: Cap on fund limit
A22: Confidence Factor | C22: 0.9 | E22: Take the market price and reduce the value by this for market fluctuations. Ex 100% but we assume 85% in case of price changes
A23: Turbine Delivery Estimate | C23: 28 | E23: Months to deliver turbine after order placed
A24: Graphene Switch | C24: Y | E24: Y says we will produce graphene
A25: Graphene reduction in Carbon Black | C25: 0.8 | E25: If we produce graphene we lose some of our carbon black yield. This value reflects what we will retain
A26: RNG Switch | C26: N | E26: N says we will produce electric Y says we will produce RNG
A27: Tires Only Switch | C27: N | E27: N says we will process both tires and MSW and Y means only tires and no MSW is processed for the entire facility
A29: Item | B29: Units | C29: Our price for confidence | D29: Wholesale Price | E29: Source
A30: Electrical price | B30: $/MWh | C30: =IF(C26="N",D30,(0)) -> 66.55 | D30: 66.55 | E30: No power production would be at this plant
A31: Power Production Year 4 - 25 | B31: MWh | C31: ='Power Production'!E30 -> 37.335738 | E31: Based on Power Production Worksheet. Parasitic load will fluctuate so assumed the highest parasitic load value
A32: Power Production Year 1 - 3 | B32: MWh | C32: =SUM(C31-10) -> 27.335738 | E32: Bitcoin HW power usage reduces output by 10 MWh
A33: Activated Carbon Ash | B33: $/MT | C33: =SUM(D33 * $C$22) -> 630 | D33: 700 | E33: https://www.engr.psu.edu/ce/courses/ce584/concrete/library/materials/Altmaterials/Class%20C%20Fly%20Ash.htm activated carbon pricing is over $1,100 a MT https://www.procurementresource.com/resource-center/activated-carbon-price-trends
A34: Carbon Black | B34: $/MT | C34: =SUM(D34 * $C$22) -> 900 | D34: 1000 | E34: https://bohanchem.en.made-in-china.com/product/tqOEBzJPJbYL/China-Carbon-Black-N339-for-Rubber-Industry.html
A35: Graphene | B35: $/MT | C35: =SUM(D35 * $C$22) -> 9000 | D35: 10000 | E35: https://www.alibaba.com/product-detail/High-Quality-Graphene-Powder-Nanoscale-Graphene_1600768680095.html?spm=a2700.7735675.0.0.4a7d0voQ0voQof&s=p
A36: Aluminum | B36: $/MT | C36: =SUM(D36 * $C$22) -> 1917 | D36: 2130 | E36: https://www.barchart.com/futures/european/major-commodities Took lowest price over 52 week range
A37: Ferrous Metals | B37: $/MT | C37: =SUM(D37 * $C$22) -> 180 | D37: 200 | E37: https://www.lme.com/Metals/Ferrous/Steel-Scrap#tabIndex=0; Current contract is at $200 MT
A38: Non-Ferrous Metals | B38: $/MT | C38: =SUM(D38 * $C$22) -> 7695 | D38: 8550 | E38: https://www.lme.com/Metals/Non-ferrous#tabIndex=0 (copper, aluminium, zinc, Nickel, lead
A39: Steel from Tires | B39: $/MT | C39: =SUM(D39 * $C$22) -> 237.6 | D39: 264 | E39: https://www.barchart.com/futures/european/major-commodities Took lowest price over 52 week range
A40: Steel, OTR Tires | B40: $/MT | C40: =SUM(D40 * $C$22) -> 270 | D40: 300 | E40: https://www.lme.com/Metals/Ferrous/Steel-Scrap#tabIndex=0
A41: MSW tipping fees | B41: $/MT | C41: -7 | D41: 70 | E41: Estimated tip fee received is $70 MT with 20% reduction
...

Sheet Inputs
P1: Aluminum ($/ST)
B2: Byproduct prices | C2: Unit | D2: $ | F2: Costs | G2: Annual Costs ($) | H2: Monthly Costs ($) | J2: Escalation | K2: Annual | L2: Monthly | O2: =Summary!$H$12 -> 0.39179596 | P2: 750 | Q2: 760 | R2: 770 | S2: 780 | T2: 790 | U2: 800 | V2: 810 | W2: 820 | X2: 830 | Y2: 840 | Z2: 850
B3: ='Data Sources'!A33 -> Activated Carbon Ash | C3: $/MT | D3: ='Data Sources'!C33 -> 630 | F3: I-ERP | J3: Inflation | K3: 0.02 | L3: =K3/12 -> 0.0016666667 | N3: ST / day | O3: 2.5 | P3: 0.36696042 | Q3: 0.36704172 | R3: 0.36712303 | S3: 0.36720433 | T3: 0.36728563 | U3: 0.36736694 | V3: 0.36744824 | W3: 0.36752955 | X3: 0.36761087 | Y3: 0.36769218 | Z3: 0.36777349
B4: ='Data Sources'!A36 -> Aluminum | C4: $/MT | D4: ='Data Sources'!C36 -> 1917 | F4: =Financials!B40 -> Employee Cost | G4: ='Emp Labor Cost'!Z117 -> 4788734.6 | H4: =G4/12 -> 399061.21 | J4: PPA or RNG | K4: 0 | L4: =K4/12 -> 0 | O4: 2.75 | P4: 0.3675702 | Q4: 0.36765965 | R4: 0.36774909 | S4: 0.36783854 | T4: 0.36792799 | U4: 0.36801744 | V4: 0.36810688 | W4: 0.36819634 | X4: 0.36828579 | Y4: 0.36837525 | Z4: 0.3684647
B5: ='Data Sources'!A37 -> Ferrous Metals | C5: $/MT | D5: ='Data Sources'!C37 -> 180 | F5: =Financials!B41 -> Turbine LTMA Cost 5 year term | G5: ='Data Sources'!C81 -> 2160000 | H5: =G5/12 -> 180000 | J5: Tip Fee MSW | K5: 0 | L5: =K5/12 -> 0 | O5: 3 | P5: 0.36818008 | Q5: 0.36827766 | R5: 0.36837525 | S5: 0.36847283 | T5: 0.36857043 | U5: 0.36866801 | V5: 0.36876561 | W5: 0.36886321 | X5: 0.3689608 | Y5: 0.36905841 | Z5: 0.36915601
B6: ='Data Sources'!A38 -> Non-Ferrous Metals | C6: $/MT | D6: ='Data Sources'!C38 -> 7695 | F6: =Financials!B42 -> Pyrolysis LTMA Cost yrs. 3+ | G6: ='Data Sources'!C82 -> 250000 | H6: =G6/12 -> 20833.333 | J6: Tip Fee Tire | K6: 0 | L6: =K6/12 -> 0 | O6: 3.25 | P6: 0.36879001 | Q6: 0.36889574 | R6: 0.36900148 | S6: 0.3691072 | T6: 0.36921294 | U6: 0.36931868 | V6: 0.36942669 | W6: 0.36953244 | X6: 0.36963817 | Y6: 0.36974393 | Z6: 0.36984966
B7: ='Data Sources'!A39 -> Steel from Tires | C7: $/MT | D7: ='Data Sources'!C39 -> 237.6 | F7: =Financials!B43 -> Total O&M | G7: ='Data Sources'!C83 -> 1537000 | H7: =G7/12 -> 128083.33 | J7: Sugar Beet Pulp Tipping Fee | K7: 0 | L7: =K7/12 -> 0 | O7: 3.37 | P7: 0.36908281 | Q7: 0.36919245 | R7: 0.36930209 | S7: 0.369414 | T7: 0.36952365 | U7: 0.3696333 | V7: 0.36974295 | W7: 0.3698526 | X7: 0.36996225 | Y7: 0.37007191 | Z7: 0.37018157
B8: ='Data Sources'!A40 -> Steel, OTR Tires | C8: $/MT | D8: ='Data Sources'!C40 -> 270 | F8: =Financials!B44 -> All insurance for the plant and risks | G8: ='Data Sources'!C91 -> 7511416.3 | H8: =G8/12 -> 625951.36 | J8: Cargill Grass Tip Fee | K8: 0 | L8: =K8/12 -> 0 | O8: 3.5 | P8: 0.36940228 | Q8: 0.36951616 | R8: 0.36963004 | S8: 0.36974393 | T8: 0.36985781 | U8: 0.36997169 | V8: 0.37008558 | W8: 0.37019946 | X8: 0.37031335 | Y8: 0.37042726 | Z8: 0.37054115
B9: ='Data Sources'!A34 -> Carbon Black | C9: $/MT | D9: ='Data Sources'!C34 -> 900 | F9: =Financials!B46 -> IT outsourced | G9: ='Data Sources'!C93 -> 80000 | H9: =G9/12 -> 6666.6667 | J9: Commodity price | K9: 0.02 | L9: =K9/12 -> 0.0016666667 | O9: 3.75 | P9: 0.37001236 | Q9: 0.37013438 | R9: 0.37025641 | S9: 0.37037844 | T9: 0.37050048 | U9: 0.37062251 | V9: 0.37074454 | W9: 0.37086659 | X9: 0.37098863 | Y9: 0.37111067 | Z9: 0.37123273
B10: ='Data Sources'!A35 -> Graphene | C10: $/MT | D10: ='Data Sources'!C35 -> 9000 | F10: =Financials!B47 -> Utilities | G10: ='Data Sources'!C94 -> 200000 | H10: =G10/12 -> 16666.667 | J10: OPEX | K10: 0.02 | L10: =K10/12 -> 0.0016666667 | O10: 4 | P10: 0.37062251 | Q10: 0.37075269 | R10: 0.37088286 | S10: 0.37101304 | T10: 0.37114323 | U10: 0.3712734 | V10: 0.3714036 | W10: 0.37153379 | X10: 0.37166399 | Y10: 0.37179419 | Z10: 0.37192439
B11: ='Data Sources'!A41 -> MSW tipping fees | C11: $/MT | D11: ='Data Sources'!C41 -> -7 | F11: =Financials!B49 -> Electricity | G11: ='Data Sources'!C95 -> 0 | H11: =G11/12 -> 0 | J11: Tax benefit | K11: 0.02 | L11: =K11/12 -> 0.0016666667
B12: ='Data Sources'!A42 -> Tire tipping fees | C12: $/MT | D12: ='Data Sources'!C42 -> 0 | F12: =Financials!B50 -> Accounting & Auditing | G12: ='Data Sources'!C97 -> 85000 | H12: =G12/12 -> 7083.3333 | J12: Property Tax | K12: 0 | L12: =K12/12 -> 0 | P12: Ferrous Metals ($/ST)
B13: ='Data Sources'!A43 -> Renewable Energy Credits | C13: $/MWh | D13: ='Data Sources'!C43 -> 0 | F13: =Financials!B51 -> Office Supplies | G13: ='Data Sources'!C98 -> 75000 | H13: =G13/12 -> 6250 | J13: Testing Fraction | K13: 1 | L13: =K13 -> 1 | O13: =Summary!$H$12 -> 0.39179596 | P13: 105 | Q13: 110 | R13: 115 | S13: 120 | T13: 125 | U13: 135.17 | V13: =U13+5 -> 140.17 | W13: =V13+5 -> 145.17 | X13: =W13+5 -> 150.17 | Y13: =X13+5 -> 155.17 | Z13: =Y13+5 -> 160.17
B14: ='Data Sources'!A44 -> Carbon Credits | C14: $/ST | D14: ='Data Sources'!C44 -> 0 | F14: =Financials!B52 -> Gas Transmission Costs | G14: ='Data Sources'!C99 -> 0 | H14: =G14/12 -> 0 | J14: Employee Labor Escalation | K14: 0.01 | L14: =K14/12 -> 0.00083333333 | N14: ST / day | O14: 8.5 | P14: 0.39069952 | Q14: 0.39083828 | R14: 0.39097704 | S14: 0.39111809 | T14: 0.39125686 | U14: 0.39153913 | V14: 0.3916779 | W14: 0.39181668 | X14: 0.39195547 | Y14: 0.39209425 | Z14: 0.39223303
B15: ='Data Sources'!A45 -> Light Oil Sale | C15: ='Data Sources'!B45 -> $/barrel | D15: ='Data Sources'!C45 -> 0 | F15: =Financials!B53 -> Permit Renewals | G15: ='Data Sources'!C100 -> 75000 | H15: =G15/12 -> 6250 | O15: 8.75 | P15: 0.39078522 | Q15: 0.39092807 | R15: 0.3910732 | S15: 0.39121605 | T15: 0.39135889 | U15: 0.39164947 | V15: 0.39179233 | W15: 0.39193519 | X15: 0.39207806 | Y15: 0.39222092 | Z15: 0.39236379
B16: ='Data Sources'!A46 -> Diesel | C16: $/Liter | D16: =SUM('Data Sources'!C46/'Data Sources'!$C$72) -> 0 | F16: =Financials!B54 -> Property Taxes | G16: ='Data Sources'!C101 -> 85000 | H16: =G16/12 -> 7083.3333 | O16: 9 | P16: 0.39087093 | Q16: 0.39102014 | R16: 0.39116707 | S16: 0.391314 | T16: 0.39146094 | U16: 0.39175981 | V16: 0.39190676 | W16: 0.39205371 | X16: 0.39220065 | Y16: 0.3923476 | Z16: 0.39249457
B17: ='Data Sources'!A47 -> JP | C17: $/Liter | D17: =SUM('Data Sources'!C47/'Data Sources'!$C$72) -> 0 | F17: =Financials!B55 -> Miscellaneous | G17: ='Data Sources'!C102 -> 100000 | H17: =G17/12 -> 8333.3333 | O17: 9.37 | P17: 0.39100006 | Q17: 0.39115303 | R17: 0.391306 | S17: 0.39145898 | T17: 0.39161195 | U17: 0.39192312 | V17: 0.39207612 | W17: 0.39222911 | X17: 0.3923821 | Y17: 0.3925351 | Z17: 0.3926881
B18: ='Data Sources'!A48 -> Gas | C18: $/Liter | D18: =SUM('Data Sources'!C48/'Data Sources'!$C$72) -> 0 | F18: =Financials!B45 -> Land Rental | G18: ='Data Sources'!C103 -> 100000 | H18: =SUM(G18/12) -> 8333.3333 | O18: 9.5 | P18: 0.39104462 | Q18: 0.39119973 | R18: 0.39135482 | S18: 0.39150992 | T18: 0.39166501 | U18: 0.39198051 | V18: 0.39213561 | W18: 0.39229073 | X18: 0.39244586 | Y18: 0.39260098 | Z18: 0.39275611
B19: ='Data Sources'!A49 -> Lube oil | C19: $/Liter | D19: =SUM('Data Sources'!C49/'Data Sources'!$C$72) -> 0 | O19: 9.75 | P19: 0.39113033 | Q19: 0.39128951 | R19: 0.39144869 | S19: 0.39160787 | T19: 0.39176705 | U19: 0.39209085 | V19: 0.39225006 | W19: 0.39240926 | X19: 0.39256846 | Y19: 0.39272767 | Z19: 0.39288688
B20: ='Data Sources'!A50 -> Petroleum Coke | C20: $/Liter | D20: =SUM('Data Sources'!C50/'Data Sources'!$C$72) -> 0 | F20: Tax | O20: 10 | P20: 0.39121605 | Q20: 0.3913793 | R20: 0.39154257 | S20: 0.39170583 | T20: 0.39186911 | U20: 0.3922012 | V20: 0.39236448 | W20: 0.39252778 | X20: 0.39269107 | Y20: 0.39285436 | Z20: 0.39301766
B21: ='Data Sources'!A51 -> RNG Sale price | C21: $ / MMBTU | D21: ='Data Sources'!C51 -> 0
B22: Plant Production | F22: Federal Corporate Income Tax Rate | G22: 0.2 | H22: Current US tax code
B23: Power (PPA Px) | C23: $/MWh | D23: ='Data Sources'!C30 -> 66.55 | F23: Colorado Corporate Income Tax Rate | G23: 0 | H23: N/A plant is not in Colorado | P23: Steel from Tires ($/ST)
B24: Net capacity | F24: Investment Tax Credit | H24: Month | O24: =Summary!$H$12 -> 0.39179596 | P24: 105 | Q24: =P24+5 -> 110 | R24: =Q24+5 -> 115 | S24: =R24+5 -> 120 | T24: =S24+5 -> 125 | U24: 127.08 | V24: 130 | W24: =V24+5 -> 135 | X24: =W24+5 -> 140 | Y24: =X24+5 -> 145 | Z24: =Y24+5 -> 150
B25: Power year 4 through 25 | C25: MW/Hour | D25: ='Data Sources'!C31 -> 37.335738 | F25: Tax Incentive (Years) | G25: 10 | H25: =G25*12 -> 120 | N25: ST / day | O25: 15 | P25: 0.38529728 | Q25: 0.38554423 | R25: 0.38578892 | S25: 0.38603362 | T25: 0.38627833 | U25: 0.38638013 | V25: 0.38652305 | W25: 0.38676777 | X25: 0.38701251 | Y25: 0.38725725 | Z25: 0.38750201
B26: Power year 1 through 3 | C26: MW/Hour | D26: ='Data Sources'!C32 -> 27.335738 | F26: Maintenance Fund | O26: 17.5 | P26: 0.38615597 | Q26: 0.38644148 | R26: 0.38672698 | S26: 0.38701251 | T26: 0.38729804 | U26: 0.38741683 | V26: 0.3875836 | W26: 0.38786915 | X26: 0.38815473 | Y26: 0.38844251 | Z26: 0.3887281
B27: =B3 -> Activated Carbon Ash | C27: MT/day | D27: ='Data Sources'!C59 -> 67.544634 | F27: Contribution (% of Cashflow) | G27: ='Data Sources'!C20 -> 0.05 | O27: 19.19 | P27: 0.38673498 | Q27: 0.38704807 | R27: 0.38736119 | S27: 0.38767431 | T27: 0.38798746 | U27: 0.38811774 | V27: 0.38830282 | W27: 0.38861598 | X27: 0.38892917 | Y27: 0.38924236 | Z27: 0.38955558
B28: =B4 -> Aluminum | C28: MT/day | D28: ='Data Sources'!C60 -> 4.95 | F28: Maximum Fund Amount | G28: ='Data Sources'!C21 -> 45000000 | H28: cap at the maximum placed into the fund by user description | O28: 20 | P28: 0.38701251 | Q28: 0.38733884 | R28: 0.38766518 | S28: 0.38799154 | T28: 0.38832012 | U28: 0.38845589 | V28: 0.3886465 | W28: 0.38897291 | X28: 0.38929933 | Y28: 0.38962576 | Z28: 0.38995221
B29: =B5 -> Ferrous Metals | C29: MT/day | D29: ='Data Sources'!C61 -> 6.82 | O29: 22.5 | P29: 0.38786915 | Q29: 0.38823852 | R29: 0.38860571 | S29: 0.38897291 | T29: 0.38934013 | U29: 0.3894929 | V29: 0.38970737 | W29: 0.39007464 | X29: 0.39044191 | Y29: 0.39080922 | Z29: 0.39117883
B30: =B6 -> Non-Ferrous Metals | C30: MT/day | D30: ='Data Sources'!C62 -> 3.3 | O30: 25 | P30: 0.3887281 | Q30: 0.38913612 | R30: 0.38954415 | S30: 0.38995221 | T30: 0.3903603 | U30: 0.39053007 | V30: 0.39076841 | W30: 0.39117883 | X30: 0.39158698 | Y30: 0.39199515 | Z30: 0.39240335
B31: =B7 -> Steel from Tires | C31: MT/day | D31: =SUM(D36 * 'Data Sources'!C74) -> 15
B32: =B8 -> Steel, OTR Tires | C32: MT/day | D32: 0 | P32: Annual Employee Costs
B33: =B9 -> Carbon Black | C33: MT/day | D33: ='Data Sources'!C63 -> 25.16 | F33: Gallons Conversion | O33: =Summary!$H$12 -> 0.39179596 | P33: =Q33-100000 -> 3570858 | Q33: =R33-100000 -> 3670858 | R33: =S33-100000 -> 3770858 | S33: =T33-100000 -> 3870858 | T33: =U33-100000 -> 3970858 | U33: 4070858 | V33: =U33+100000 -> 4170858 | W33: =V33+100000 -> 4270858 | X33: =W33+100000 -> 4370858 | Y33: =X33+100000 -> 4470858 | Z33: =Y33+100000 -> 4570858
B34: =B10 -> Graphene | C34: MT/day | D34: ='Data Sources'!C64 -> 5.661 | F34: =SUM(D37 / 'Data Sources'!$C$72) -> 6704.1199 | H34: Wholesale Price per gallon | N34: Total O&M Expense | O34: =O35-100000 -> 2848800 | P34: 0.39063134 | Q34: 0.38976352 | R34: 0.38889589 | S34: 0.38802628 | T34: 0.38715906 | U34: 0.38629205 | V34: 0.38542297 | W34: 0.38455637 | X34: 0.38368999 | Y34: 0.38282155 | Z34: 0.38195559
B35: MSW consumption | C35: MT/day | D35: =SUM('Data Sources'!C53) -> 550 | F35: =SUM(D39 / 'Data Sources'!$C$72) -> 1340.824 | O35: =O36-100000 -> 2948800 | P35: 0.38973696 | Q35: 0.38886929 | R35: 0.38799964 | S35: 0.38713236 | T35: 0.38626531 | U35: 0.3853962 | V35: 0.38452955 | W35: 0.38366312 | X35: 0.38279465 | Y35: 0.38192864 | Z35: 0.38106286
B36: Gross Tires Processed | C36: MT/day | D36: ='Data Sources'!C54 -> 100 | F36: =SUM(D40 / 'Data Sources'!$C$72) -> 1340.824 | O36: =O37-100000 -> 3048800 | P36: 0.38884268 | Q36: 0.38797298 | R36: 0.38710567 | S36: 0.38623857 | T36: 0.38536941 | U36: 0.38450273 | V36: 0.38363625 | W36: 0.38276773 | X36: 0.38190168 | Y36: 0.38103586 | Z36: 0.38017026
B37: Oil from Tires | C37: Liters/day | D37: =SUM('Data Sources'!C66*'Data Sources'!C72) -> 25377.843 | F37: =SUM(D41 / 'Data Sources'!$C$72) -> 1340.824 | H37: 1.881 | J37: =SUM(H37/'Data Sources'!C72) -> 0.49690786 | O37: =O38-100000 -> 3148800 | P37: 0.38794633 | Q37: 0.38707897 | R37: 0.38621183 | S37: 0.38534263 | T37: 0.38447589 | U37: 0.38360938 | V37: 0.38274081 | W37: 0.38187472 | X37: 0.38100885 | Y37: 0.3801432 | Z37: 0.37927558
B38: =B15 -> Light Oil Sale | C38: Barrel/day | D38: =SUM('Data Sources'!C66/42) -> 159.6219 | F38: =SUM(D42 / 'Data Sources'!$C$72) -> 1340.824 | O38: 3248800 | P38: 0.38705227 | Q38: 0.38618509 | R38: 0.38531584 | S38: 0.38444906 | T38: 0.3835825 | U38: 0.3827139 | V38: 0.38184776 | W38: 0.38098183 | X38: 0.38011397 | Y38: 0.37924848 | Z38: 0.37838323
B39: Diesel | C39: Liters/day | D39: =SUM($D$37 * 'Data Sources'!C67) -> 5075.5685 | F39: =SUM(D43 / 'Data Sources'!$C$72) -> 1340.824 | O39: =O38+100000 -> 3348800 | P39: 0.38615834 | Q39: 0.38528904 | R39: 0.38442222 | S39: 0.38355562 | T39: 0.38268697 | U39: 0.38182078 | V39: 0.38095482 | W39: 0.3800869 | X39: 0.37922137 | Y39: 0.37835608 | Z39: 0.37749102
B40: JP | C40: Liters/day | D40: =SUM($D$37 * 'Data Sources'!C68) -> 5075.5685 | O40: =O39+100000 -> 3448800 | P40: 0.38526224 | Q40: 0.38439539 | R40: 0.38352874 | S40: 0.38266004 | T40: 0.38179381 | U40: 0.38092781 | V40: 0.38005984 | W40: 0.37919427 | X40: 0.37832893 | Y40: 0.37746155 | Z40: 0.37659665
...

Sheet Project Equity %
B2: Total Project Equity | C2: =Summary!D3 -> 64955662
B4: Total Equity Contributed
B5: CREC Equity | C5: 0 | D5: 0.25
B6: Outside Equity | C6: =$C$2 -> 64955662 | D6: =1-D5 -> 0.75
C8: Project Level Equity Ownership %
B9: $USD | C9: =D9-0.05 -> 0.25 | D9: =E9-0.05 -> 0.3 | E9: =F9-0.05 -> 0.35 | F9: =G9-0.05 -> 0.4 | G9: =H9-0.05 -> 0.45 | H9: =I9-0.05 -> 0.5 | I9: =J9-0.05 -> 0.55 | J9: =K9-0.05 -> 0.6 | ... L9: =M9-0.05 -> 0.7 | M9: =D6 -> 0.75
B10: Equity Contributions | C10: =(C9/$D$6)*$C$6 -> 21651887 | D10: =(D9/$D$6)*$C$6 -> 25982265 | E10: =(E9/$D$6)*$C$6 -> 30312642 | F10: =(F9/$D$6)*$C$6 -> 34643020 | G10: =(G9/$D$6)*$C$6 -> 38973397 | H10: =(H9/$D$6)*$C$6 -> 43303774 | I10: =(I9/$D$6)*$C$6 -> 47634152 | J10: =(J9/$D$6)*$C$6 -> 51964529 | ... L10: =(L9/$D$6)*$C$6 -> 60625284 | M10: =C6 -> 64955662
B11: Equity Cash Flows | C11: =C$9*Summary!$H$11 -> 2.8234519e+08 | D11: =D$9*Summary!$H$11 -> 3.3881422e+08 | E11: =E$9*Summary!$H$11 -> 3.9528326e+08 | F11: =F$9*Summary!$H$11 -> 4.517523e+08 | G11: =G$9*Summary!$H$11 -> 5.0822133e+08 | H11: =H$9*Summary!$H$11 -> 5.6469037e+08 | I11: =I$9*Summary!$H$11 -> 6.2115941e+08 | J11: =J$9*Summary!$H$11 -> 6.7762844e+08 | ... M11: =M$9*Summary!$H$11 -> 8.4703556e+08
B12: Net Present Value | C12: =C$9*Summary!$H$13 -> 58267428 | D12: =D$9*Summary!$H$13 -> 69920914 | E12: =E$9*Summary!$H$13 -> 81574399 | F12: =F$9*Summary!$H$13 -> 93227885 | G12: =G$9*Summary!$H$13 -> 1.0488137e+08 | H12: =H$9*Summary!$H$13 -> 1.1653486e+08 | I12: =I$9*Summary!$H$13 -> 1.2818834e+08 | J12: =J$9*Summary!$H$13 -> 1.3984183e+08 | ... M12: =M$9*Summary!$H$13 -> 1.7480228e+08

Sheet CapEx
A1: Value by Country amount on orgin amount | C1: USA | D1: =SUM(D11+D12+D13+D14+D15+D16+D46+D47+D48+D49+D50+D51+D52+D53+D54+D55+D56+D57+D58+D59+D60+D61+D62+D63+D64+D65+D66+D69+D73+D74+D75+D76+D84+D85+D86+D88+D98+D101+D102+D87) -> 1.1754615e+08
C2: Djibouti | D2: =SUM(D103+D112) -> 7146511.8
C3: India | D3: =SUM(D89+D90+D91+D92+D93+D94) -> 2240000
C4: UK | D4: =SUM(D70+D71+D72+D67+D77+D78+D79+D80+D82+D83+D68+D95+D96+D97+D99+D100+D104+D105+D108+D110) -> 1.073307e+08
C5: Finland | D5: =SUM(F10+F18+F19+F35+F36) -> 2583373.3 | F5: Tire Only Processing column flag is whether the equipment would be used for a tire only facility. This provides only a high level assumption. Design would be required to solidify the numbers. Also the MSW value in Data Sources needs to be set to "0"
C6: Germany | D6: =SUM(D18+D19+D35+D36+D20+D21+D22+D23+D24+D25+D26+D27+D28+D29+D30+D31+D32+D33+D34+D37+D38+D39+D40+D41+D42+D43+D44) -> 9149476.3
C7: Holland | D7: =SUM(D45) -> 1148000 | N7: Month Plant Online | O7: ='Data Sources'!C4 -> 16
C8: Total Capital Expenditures | D8: =SUM(D1:D7) -> 2.471442e+08 | J8: Draw Down schedule for equipment purchase
B9: STAGE | C9: Equipment | D9: $ | E9: Comments | F9: Vendor price | G9: Country Purchase | H9: Country Origin | I9: Tire Only Processing | J9: Upon order | K9: Complete before shipment | L9: Delivered and installed | M9: Lead Time in Months | N9: Capital Expenditures Timeline | R9: Depreciation Schedule
B10: 1 | C10: Base Primary Shredder | D10: =IF(I10="N",F10,0) -> 700000 | F10: 700000 | G10: NC, USA | H10: Finland | I10: =IF('Data Sources'!$C$27="N","N","Y") -> N | J10: 0.5 | K10: 0.4 | L10: 0.1 | M10: 8 | N10: Month | O10: Period | P10: Cumulative | R10: Year | S10: Annual | T10: Month | U10: Monthly | V10: Cumulative
B11: 1 | C11: CM4R Liberator Unit Price | D11: =IF(I11="Y",F11,0) -> 1203500 | F11: 1203500 | G11: FL, USA | H11: FL, USA | I11: Y | J11: 0.5 | K11: 0.4 | L11: 0.1 | M11: 8 | N11: 1 | O11: 0.21716081 | P11: =SUM($O$11:O11) -> 0.21716081 | R11: 1 | S11: =1/7 -> 0.14285714 | T11: =O7+11 -> 27 | U11: =S11/12 -> 0.011904762 | V11: =SUM($S$11:S11) -> 0.14285714
B12: 1 | C12: Spare parts for the year | D12: =IF(I12="Y",F12,0) -> 34573.8 | F12: 34573.8 | G12: FL, USA | H12: FL, USA | I12: Y | J12: 0.5 | K12: 0.4 | L12: 0.1 | M12: 8 | N12: 2 | O12: 0.068334204 | P12: =SUM($O$11:O12) -> 0.28549501 | R12: =R11+1 -> 2 | S12: =1/7 -> 0.14285714 | T12: =T11+12 -> 39 | U12: =S12/12 -> 0.011904762 | V12: =SUM($S$11:S12) -> 0.28571429
B13: 1 | C13: Eagle OTR debeader | D13: 446430 | E13: 3/10/2025 updated | F13: 407774 | G13: NE, USA | H13: NE, USA | I13: Y | J13: 0.5 | K13: 0.4 | L13: 0.1 | M13: 8 | N13: 3 | O13: 0.055080355 | P13: =SUM($O$11:O13) -> 0.34057537 | R13: =R12+1 -> 3 | S13: =1/7 -> 0.14285714 | T13: =T12+12 -> 51 | U13: =S13/12 -> 0.011904762 | V13: =SUM($S$11:S13) -> 0.42857143
B14: 1 | C14: Eagle punch cutter 2 | D14: 304858 | E14: 3/10/2025 updated | F14: 231396 | G14: NE, USA | H14: NE, USA | I14: Y | J14: 0.5 | K14: 0.4 | L14: 0.1 | M14: 8 | N14: 4 | O14: 0.035148729 | P14: =SUM($O$11:O14) -> 0.3757241 | R14: =R13+1 -> 4 | S14: =1/7 -> 0.14285714 | T14: =T13+12 -> 63 | U14: =S14/12 -> 0.011904762 | V14: =SUM($S$11:S14) -> 0.57142857
B15: 1 | C15: Eagle titan 2 | D15: 516512 | E15: 3/10/2025 updated | F15: 507209 | G15: NE, USA | H15: NE, USA | I15: Y | J15: 0.5 | K15: 0.4 | L15: 0.1 | M15: 8 | N15: 5 | O15: 0.083342618 | P15: =SUM($O$11:O15) -> 0.45906672 | R15: =R14+1 -> 5 | S15: =1/7 -> 0.14285714 | T15: =T14+12 -> 75 | U15: =S15/12 -> 0.011904762 | V15: =SUM($S$11:S15) -> 0.71428571
B16: 1 | C16: Cuber for MSW Warren n Baerg | D16: =IF(I16="N",F16,0) -> 2685974 | F16: 2685974 | G16: CA, USA | H16: CA, USA | I16: =IF('Data Sources'!$C$27="N","N","Y") -> N | J16: 0.5 | K16: 0.4 | L16: 0.1 | M16: 8 | N16: 6 | O16: 0.10345018 | P16: =SUM($O$11:O16) -> 0.56251689 | R16: =R15+1 -> 6 | S16: =1/7 -> 0.14285714 | T16: =T15+12 -> 87 | U16: =S16/12 -> 0.011904762 | V16: =SUM($S$11:S16) -> 0.85714286
B17: 1 | C17: placeholder for extra feed hoppers and associated conveyors | D17: =IF(I17="N",F17,0) -> 1200000 | F17: 1200000 | G17: CA, USA | H17: CA, USA | I17: =IF('Data Sources'!$C$27="N","N","Y") -> N | J17: 0.5 | K17: 0.4 | L17: 0.1 | M17: 8 | N17: 7 | O17: 0.090610633 | P17: =SUM($O$11:O17) -> 0.65312753 | R17: =R16+1 -> 7 | S17: =1/7 -> 0.14285714 | T17: =T16+12 -> 99 | U17: =S17/12 -> 0.011904762 | V17: =SUM($S$11:S17) -> 1
B18: 1 | C18: Position 1 Metso Pre-Shredder | D18: =IF(I18="N",F18,0) -> 648785.95 | F18: 648785.95 | G18: NC, USA | H18: Finland | I18: =IF('Data Sources'!$C$27="N","N","Y") -> N | J18: 0.5 | K18: 0.4 | L18: 0.1 | M18: 8 | N18: 8 | O18: 0.077696546 | P18: =SUM($O$11:O18) -> 0.73082407 | R18: =R17+1 -> 8 | T18: =T17+12 -> 111
B19: 1 | C19: Position 2 Shredder discharge, Magnetic separation and screen feed | D19: =IF(I19="N",F19,0) -> 128789.5 | F19: 128789.5 | G19: NC, USA | H19: Finland | I19: =IF('Data Sources'!$C$27="N","N","Y") -> N | J19: 0.5 | K19: 0.4 | L19: 0.1 | M19: 8 | N19: 9 | O19: 0.071405245 | P19: =SUM($O$11:O19) -> 0.80222932 | R19: =R18+1 -> 9 | T19: =T18+12 -> 123
B20: 1 | C20: Position 3 Cascade Screen Package | D20: =IF(I20="N",F20,0) -> 255272.59 | F20: 255272.59 | G20: NC, USA | H20: Germany | I20: =IF('Data Sources'!$C$27="N","N","Y") -> N | J20: 0.5 | K20: 0.4 | L20: 0.1 | M20: 8 | N20: 10 | O20: 0.058318105 | P20: =SUM($O$11:O20) -> 0.86054742 | R20: =R19+1 -> 10 | T20: =T19+12 -> 135
B21: 1 | C21: Westeria FlatCon 1400-11200 | D21: =IF(I21="N",F21,0) -> 53428.5 | F21: 53428.5 | G21: NC, USA | H21: Germany | I21: =IF('Data Sources'!$C$27="N","N","Y") -> N | J21: 0.5 | K21: 0.4 | L21: 0.1 | M21: 8 | N21: 11 | O21: 0.056661897 | P21: =SUM($O$11:O21) -> 0.91720932
B22: 1 | C22: Position 5 Eddie Current System | D22: =IF(I22="N",F22,0) -> 234967.15 | F22: 234967.15 | G22: NC, USA | H22: Germany | I22: =IF('Data Sources'!$C$27="N","N","Y") -> N | J22: 0.5 | K22: 0.4 | L22: 0.1 | M22: 8 | N22: 12 | O22: 0.08279068 | P22: =SUM($O$11:O22) -> 1 | Y22: Depreciation Schedule
B23: 1 | C23: Position 6 Wisteria windsifter and feed conveyor to NI includes bag house | D23: =IF(I23="N",F23,0) -> 229153.55 | F23: 229153.55 | G23: NC, USA | H23: Germany | I23: =IF('Data Sources'!$C$27="N","N","Y") -> N | J23: 0.5 | K23: 0.4 | L23: 0.1 | M23: 8 | N23: 13 | P23: =SUM($O$11:O23) -> 1 | R23: Maintenance Capital Expenditures | U23: Depreciation | Y23: ='Data Sources'!C1 -> 2026 | Z23: =SUM(Y23+1) -> 2027 | AA23: =SUM(Z23+1) -> 2028 | AB23: =SUM(AA23+1) -> 2029 | AC23: =SUM(AB23+1) -> 2030 | AD23: =SUM(AC23+1) -> 2031 | AE23: =SUM(AD23+1) -> 2032 | AF23: =SUM(AE23+1) -> 2033 | AG23: =SUM(AF23+1) -> 2034 | ... AU23: =SUM(AT23+1) -> 2048
